Workbook

Sheet compartments
A1: Ages | B1: Population (2001) | C1: S0 | D1: E0 | E1: I0 | F1: R0
A2: 0 | B2: 96676 | C2: =B2 -> 96676 | D2: =ROUND(helper!M2/26,0) -> 53 | E2: =ROUND(helper!M2/52,0) -> 26 | F2: =ROUND(B2*helper!Q2,0) -> 0
A3: 1 | B3: 92864 | C3: =B3-F3 -> 91425 | D3: =ROUND(helper!M3/26,0) -> 111 | E3: =ROUND(helper!M3/52,0) -> 55 | F3: =ROUND(B3*helper!Q3,0) -> 1439
A4: 2 | B4: 95398 | C4: =B4-F4 -> 90914 | D4: =ROUND(helper!M4/26,0) -> 239 | E4: =ROUND(helper!M4/52,0) -> 119 | F4: =ROUND(B4*helper!Q4,0) -> 4484
A5: 3 | B5: 97946 | C5: =B5-F5 -> 87137 | D5: =ROUND(helper!M5/26,0) -> 693 | E5: =ROUND(helper!M5/52,0) -> 347 | F5: =ROUND(B5*helper!Q5,0) -> 10809
A6: 4 | B6: 103862 | C6: =B6-F6 -> 73581 | D6: =ROUND(helper!M6/26,0) -> 893 | E6: =ROUND(helper!M6/52,0) -> 446 | F6: =ROUND(B6*helper!Q6,0) -> 30281
A7: 5 | B7: 110187 | C7: =B7-F7 -> 52050 | D7: =ROUND(helper!M7/26,0) -> 719 | E7: =ROUND(helper!M7/52,0) -> 360 | F7: =ROUND(B7*helper!Q7,0) -> 58137
A8: 6 | B8: 112612 | C8: =B8-F8 -> 32160 | D8: =ROUND(helper!M8/26,0) -> 406 | E8: =ROUND(helper!M8/52,0) -> 203 | F8: =ROUND(B8*helper!Q8,0) -> 80452
A9: 7 | B9: 114774 | C9: =B9-F9 -> 20400 | D9: =ROUND(helper!M9/26,0) -> 166 | E9: =ROUND(helper!M9/52,0) -> 83 | F9: =ROUND(B9*helper!Q9,0) -> 94374
A10: 8 | B10: 119484 | C10: =B10-F10 -> 15711 | D10: =ROUND(helper!M10/26,0) -> 79 | E10: =ROUND(helper!M10/52,0) -> 39 | F10: =ROUND(B10*helper!Q10,0) -> 103773
A11: 9 | B11: 124661 | C11: =B11-F11 -> 13722 | D11: =ROUND(helper!M11/26,0) -> 42 | E11: =ROUND(helper!M11/52,0) -> 21 | F11: =ROUND(B11*helper!Q11,0) -> 110939
A12: 10 | B12: 125145 | C12: =B12-F12 -> 12351 | D12: =ROUND(helper!M12/26,0) -> 27 | E12: =ROUND(helper!M12/52,0) -> 13 | F12: =ROUND(B12*helper!Q12,0) -> 112794
A13: 11 | B13: 122141 | C13: =B13-F13 -> 11185 | D13: =ROUND(helper!M13/26,0) -> 19 | E13: =ROUND(helper!M13/52,0) -> 9 | F13: =ROUND(B13*helper!Q13,0) -> 110956
A14: 12 | B14: 123122 | C14: =B14-F14 -> 10648 | D14: =ROUND(helper!M14/26,0) -> 14 | E14: =ROUND(helper!M14/52,0) -> 7 | F14: =ROUND(B14*helper!Q14,0) -> 112474
... A66: 64 | B66: 99642 | C66: =B66-F66 -> 6771 | D66: =ROUND(helper!M66/26,0) -> 0 | E66: =ROUND(helper!M66/52,0) -> 0 | F66: =ROUND(B66*helper!Q66,0) -> 92871
A67: 65+ | B67: 1544980 | C67: =B67-F67 -> 104964 | D67: =ROUND(helper!M67/26,0) -> 0 | E67: =ROUND(helper!M67/52,0) -> 0 | F67: =ROUND(B67*helper!Q67,0) -> 1440016
A68: Sum | B68: =SUM(B2:B67) -> 10200298 | C68: =SUM(C2:C67) -> 1222086 | D68: =SUM(D2:D67) -> 3521 | E68: =SUM(E2:E67) -> 1769 | F68: =SUM(F2:F67) -> 8978212

Sheet helper
A1: Ages | B1: Population(2011) | C1: Varicella: | D1: 2011 | E1: 2012 | F1: 2013 | G1: 2014 | H1: 2015 | I1: 2016 | J1: 2017 | K1: Mean | L1: Korr. Tényező (binom) | M1: Korrigált átlag | N1: age group % | O1: cumulative % | P1: Varicella, cumulative | Q1: Hány % (korr) volt már beteg
A2: 0 | B2: 88278 | D2: =Varicella!B2 -> 1245 | E2: =Varicella!C2 -> 1070 | F2: =Varicella!D2 -> 1252 | G2: =Varicella!E2 -> 1052 | H2: =Varicella!F2 -> 1577 | I2: =Varicella!G2 -> 1518 | J2: =Varicella!H2 -> 1343 | K2: 1293.8571 | L2: 0.0047475615 | M2: =K2*(1+L$70*L2) -> 1367.5691 | N2: =M2/B2 -> 0.015491619 | O2: =N2 -> 0.015491619 | P2: =M2 -> 1367.5691 | Q2: =0 -> 0
A3: 1 | B3: 91244 | D3: =Varicella!B3 -> 2342 | E3: =Varicella!C3 -> 1700 | F3: =Varicella!D3 -> 1988 | G3: =Varicella!E3 -> 1662 | H3: =Varicella!F3 -> 2581 | I3: =Varicella!G3 -> 2473 | J3: =Varicella!H3 -> 1984 | K3: 2104.2857 | L3: 0.030520038 | M3: =K3*(1+L$70*L3) -> 2874.9603 | N3: =M3/B3 -> 0.031508486 | O3: =O2+N3 -> 0.047000105 | P3: =P2+M3 -> 4242.5294 | Q3: =O2 -> 0.015491619
A4: 2 | B4: 97905 | D4: =Varicella!B4 -> 3436 | E4: =Varicella!C4 -> 2639 | F4: =Varicella!D4 -> 2665 | G4: =Varicella!E4 -> 2308 | H4: =Varicella!F4 -> 3747 | I4: =Varicella!G4 -> 3210 | J4: =Varicella!H4 -> 2685 | K4: 2955.7143 | L4: 0.091560115 | M4: =K4*(1+L$70*L4) -> 6203.2208 | N4: =M4/B4 -> 0.063359591 | O4: =O3+N4 -> 0.1103597 | P4: =P3+M4 -> 10445.75 | Q4: =O3 -> 0.047000105
A5: 3 | B5: 99516 | D5: =Varicella!B5 -> 6657 | E5: =Varicella!C5 -> 5740 | F5: =Varicella!D5 -> 5792 | G5: =Varicella!E5 -> 4713 | H5: =Varicella!F5 -> 6992 | I5: =Varicella!G5 -> 6336 | J5: =Varicella!H5 -> 5282 | K5: 5930.2857 | L5: 0.17004021 | M5: =K5*(1+L$70*L5) -> 18030.93 | N5: =M5/B5 -> 0.18118624 | O5: =O4+N5 -> 0.29154594 | P5: =P4+M5 -> 28476.68 | Q5: =O4 -> 0.1103597
A6: 4 | B6: 98302 | D6: =Varicella!B6 -> 7244 | E6: =Varicella!C6 -> 6281 | F6: =Varicella!D6 -> 6387 | G6: =Varicella!E6 -> 5225 | H6: =Varicella!F6 -> 7376 | I6: =Varicella!G6 -> 6539 | J6: =Varicella!H6 -> 5779 | K6: 6404.4286 | L6: 0.21862313 | M6: =K6*(1+L$70*L6) -> 23206.303 | N6: =M6/B6 -> 0.23607153 | O6: =O5+N6 -> 0.52761747 | P6: =P5+M6 -> 51682.984 | Q6: =O5 -> 0.29154594
A7: 5 | B7: 100143 | D7: =Varicella!B7 -> 6077 | E7: =Varicella!C7 -> 5140 | F7: =Varicella!D7 -> 5234 | G7: =Varicella!E7 -> 4560 | H7: =Varicella!F7 -> 6539 | I7: =Varicella!G7 -> 5405 | J7: =Varicella!H7 -> 4743 | K7: 5385.4286 | L7: 0.20613038 | M7: =K7*(1+L$70*L7) -> 18706.634 | N7: =M7/B7 -> 0.18679922 | O7: =O6+N7 -> 0.71441668 | P7: =P6+M7 -> 70389.618 | Q7: =O6 -> 0.52761747
A8: 6 | B8: 97778 | D8: =Varicella!B8 -> 4132 | E8: =Varicella!C8 -> 3516 | F8: =Varicella!D8 -> 3790 | G8: =Varicella!E8 -> 3200 | H8: =Varicella!F8 -> 4523 | I8: =Varicella!G8 -> 4056 | J8: =Varicella!H8 -> 3460 | K8: 3811 | L8: 0.14723599 | M8: =K8*(1+L$70*L8) -> 10544.396 | N8: =M8/B8 -> 0.10784017 | O8: =O7+N8 -> 0.82225685 | P8: =P7+M8 -> 80934.014 | Q8: =O7 -> 0.71441668
A9: 7 | B9: 93238 | D9: =Varicella!B9 -> 2362 | E9: =Varicella!C9 -> 1972 | F9: =Varicella!D9 -> 2125 | G9: =Varicella!E9 -> 1808 | H9: =Varicella!F9 -> 2551 | I9: =Varicella!G9 -> 2332 | J9: =Varicella!H9 -> 2147 | K9: 2185.2857 | L9: 0.081130033 | M9: =K9*(1+L$70*L9) -> 4312.7933 | N9: =M9/B9 -> 0.046255747 | O9: =O8+N9 -> 0.8685126 | P9: =P8+M9 -> 85246.807 | Q9: =O8 -> 0.82225685
A10: 8 | B10: 95609 | D10: =Varicella!B10 -> 1581 | E10: =Varicella!C10 -> 1363 | F10: =Varicella!D10 -> 1268 | G10: =Varicella!E10 -> 1068 | H10: =Varicella!F10 -> 1609 | I10: =Varicella!G10 -> 1564 | J10: =Varicella!H10 -> 1657 | K10: 1444.2857 | L10: 0.034770014 | M10: =K10*(1+L$70*L10) -> 2046.8997 | N10: =M10/B10 -> 0.02140907 | O10: =O9+N10 -> 0.88992167 | P10: =P9+M10 -> 87293.707 | Q10: =O9 -> 0.8685126
A11: 9 | B11: 95578 | D11: =Varicella!B11 -> 1198 | E11: =Varicella!C11 -> 804 | F11: =Varicella!D11 -> 890 | G11: =Varicella!E11 -> 647 | H11: =Varicella!F11 -> 1038 | I11: =Varicella!G11 -> 1068 | J11: =Varicella!H11 -> 1043 | K11: 955.42857 | L11: 0.011590005 | M11: =K11*(1+L$70*L11) -> 1088.3096 | N11: =M11/B11 -> 0.011386612 | O11: =O10+N11 -> 0.90130828 | P11: =P10+M11 -> 88382.017 | Q11: =O10 -> 0.88992167
A12: 10 | B12: 98251 | D12: =Varicella!B12 -> 754 | E12: =Varicella!C12 -> 608 | F12: =Varicella!D12 -> 638 | G12: =Varicella!E12 -> 520 | H12: =Varicella!F12 -> 692 | I12: =Varicella!G12 -> 761 | J12: =Varicella!H12 -> 755 | K12: 675.42857 | L12: 0.0029802869 | M12: =K12*(1+L$70*L12) -> 699.58422 | N12: =M12/B12 -> 0.0071203776 | O12: =O11+N12 -> 0.90842866 | P12: =P11+M12 -> 89081.601 | Q12: =O11 -> 0.90130828
A13: 11 | B13: 95802 | D13: =Varicella!B13 -> 553 | E13: =Varicella!C13 -> 496 | F13: =Varicella!D13 -> 510 | G13: =Varicella!E13 -> 350 | H13: =Varicella!F13 -> 460 | I13: =Varicella!G13 -> 535 | J13: =Varicella!H13 -> 482 | K13: 483.71429 | L13: 0.00058057538 | M13: =K13*(1+L$70*L13) -> 487.08428 | N13: =M13/B13 -> 0.0050842809 | O13: =O12+N13 -> 0.91351294 | P13: =P12+M13 -> 89568.685 | Q13: =O12 -> 0.90842866
A14: 12 | B14: 94455 | D14: =Varicella!B14 -> 448 | E14: =Varicella!C14 -> 341 | F14: =Varicella!D14 -> 392 | G14: =Varicella!E14 -> 287 | H14: =Varicella!F14 -> 361 | I14: =Varicella!G14 -> 392 | J14: =Varicella!H14 -> 388 | K14: 372.71429 | L14: 8.293934e-05 | M14: =K14*(1+L$70*L14) -> 373.08524 | N14: =M14/B14 -> 0.0039498728 | O14: =O13+N14 -> 0.91746281 | P14: =P13+M14 -> 89941.77 | Q14: =O13 -> 0.91351294
... A16: 14 | B16: 103351 | D16: =Varicella!B16 -> 318 | E16: =Varicella!C16 -> 233 | F16: =Varicella!D16 -> 223 | G16: =Varicella!E16 -> 185 | H16: =Varicella!F16 -> 203 | I16: =Varicella!G16 -> 253 | J16: =Varicella!H16 -> 243 | K16: 236.85714 | L16: 5.0221174e-07 | M16: =K16*(1+L$70*L16) -> 236.85857 | N16: =M16/B16 -> 0.0022917879 | O16: =O15+N16 -> 0.92271214 | P16: =P15+M16 -> 90469.086 | Q16: =O15 -> 0.92042036
A17: 15 | B17: 112446 | D17: =Varicella!B$22/5 -> 129.6 | E17: =Varicella!C$22/5 -> 91.6 | F17: =Varicella!D$22/5 -> 96.6 | G17: =Varicella!E$22/5 -> 87 | H17: =Varicella!F$22/5 -> 93.8 | I17: =Varicella!G$22/5 -> 94.4 | J17: =Varicella!H$22/5 -> 95 | K17: 98.285714 | L17: 1.4348907e-08 | M17: =K17*(1+L$70*L17) -> 98.285731 | N17: =M17/B17 -> 0.0008740705 | O17: =O16+N17 -> 0.92358621 | P17: =P16+M17 -> 90567.372 | Q17: =O16 -> 0.92271214
A18: 16 | B18: 114846 | D18: =Varicella!B$22/5 -> 129.6 | E18: =Varicella!C$22/5 -> 91.6 | F18: =Varicella!D$22/5 -> 96.6 | G18: =Varicella!E$22/5 -> 87 | H18: =Varicella!F$22/5 -> 93.8 | I18: =Varicella!G$22/5 -> 94.4 | J18: =Varicella!H$22/5 -> 95 | K18: 98.285714 | L18: 0 | M18: =K18*(1+L$70*L18) -> 98.285714 | N18: =M18/B18 -> 0.00085580442 | O18: =O17+N18 -> 0.92444202 | P18: =P17+M18 -> 90665.657 | Q18: =O17 -> 0.92358621
A19: 17 | B19: 120012 | D19: =Varicella!B$22/5 -> 129.6 | E19: =Varicella!C$22/5 -> 91.6 | F19: =Varicella!D$22/5 -> 96.6 | G19: =Varicella!E$22/5 -> 87 | H19: =Varicella!F$22/5 -> 93.8 | I19: =Varicella!G$22/5 -> 94.4 | J19: =Varicella!H$22/5 -> 95 | K19: 98.285714 | L19: 0 | M19: =K19*(1+L$70*L19) -> 98.285714 | N19: =M19/B19 -> 0.00081896572 | O19: =O18+N19 -> 0.92526098 | P19: =P18+M19 -> 90763.943 | Q19: =O18 -> 0.92444202
A20: 18 | B20: 120532 | D20: =Varicella!B$22/5 -> 129.6 | E20: =Varicella!C$22/5 -> 91.6 | F20: =Varicella!D$22/5 -> 96.6 | G20: =Varicella!E$22/5 -> 87 | H20: =Varicella!F$22/5 -> 93.8 | I20: =Varicella!G$22/5 -> 94.4 | J20: =Varicella!H$22/5 -> 95 | K20: 98.285714 | L20: 0 | M20: =K20*(1+L$70*L20) -> 98.285714 | N20: =M20/B20 -> 0.00081543253 | O20: =O19+N20 -> 0.92607642 | P20: =P19+M20 -> 90862.229 | Q20: =O19 -> 0.92526098
A21: 19 | B21: 125698 | D21: =Varicella!B$22/5 -> 129.6 | E21: =Varicella!C$22/5 -> 91.6 | F21: =Varicella!D$22/5 -> 96.6 | G21: =Varicella!E$22/5 -> 87 | H21: =Varicella!F$22/5 -> 93.8 | I21: =Varicella!G$22/5 -> 94.4 | J21: =Varicella!H$22/5 -> 95 | K21: 98.285714 | L21: 0 | M21: =K21*(1+L$70*L21) -> 98.285714 | N21: =M21/B21 -> 0.00078191948 | O21: =O20+N21 -> 0.92685834 | P21: =P20+M21 -> 90960.515 | Q21: =O20 -> 0.92607642
A22: 20 | B22: 129024 | D22: =Varicella!B$23/10 -> 38.4 | E22: =Varicella!C$23/10 -> 28.6 | F22: =Varicella!D$23/10 -> 29.6 | G22: =Varicella!E$23/10 -> 26.1 | H22: =Varicella!F$23/10 -> 26.6 | I22: =Varicella!G$23/10 -> 26.9 | J22: =Varicella!H$23/10 -> 27.2 | K22: 29.057143 | L22: 0 | M22: =K22*(1+L$70*L22) -> 29.057143 | N22: =M22/B22 -> 0.00022520727 | O22: =O21+N22 -> 0.92708354 | P22: =P21+M22 -> 90989.572 | Q22: =O21 -> 0.92685834
A23: 21 | B23: 125092 | D23: =Varicella!B$23/10 -> 38.4 | E23: =Varicella!C$23/10 -> 28.6 | F23: =Varicella!D$23/10 -> 29.6 | G23: =Varicella!E$23/10 -> 26.1 | H23: =Varicella!F$23/10 -> 26.6 | I23: =Varicella!G$23/10 -> 26.9 | J23: =Varicella!H$23/10 -> 27.2 | K23: 29.057143 | L23: 0 | M23: =K23*(1+L$70*L23) -> 29.057143 | N23: =M23/B23 -> 0.00023228618 | O23: =O22+N23 -> 0.92731583 | P23: =P22+M23 -> 91018.629 | Q23: =O22 -> 0.92708354
A24: 22 | B24: 122247 | D24: =Varicella!B$23/10 -> 38.4 | E24: =Varicella!C$23/10 -> 28.6 | F24: =Varicella!D$23/10 -> 29.6 | G24: =Varicella!E$23/10 -> 26.1 | H24: =Varicella!F$23/10 -> 26.6 | I24: =Varicella!G$23/10 -> 26.9 | J24: =Varicella!H$23/10 -> 27.2 | K24: 29.057143 | L24: 0 | M24: =K24*(1+L$70*L24) -> 29.057143 | N24: =M24/B24 -> 0.00023769207 | O24: =O23+N24 -> 0.92755352 | P24: =P23+M24 -> 91047.686 | Q24: =O23 -> 0.92731583
A25: 23 | B25: 121139 | D25: =Varicella!B$23/10 -> 38.4 | E25: =Varicella!C$23/10 -> 28.6 | F25: =Varicella!D$23/10 -> 29.6 | G25: =Varicella!E$23/10 -> 26.1 | H25: =Varicella!F$23/10 -> 26.6 | I25: =Varicella!G$23/10 -> 26.9 | J25: =Varicella!H$23/10 -> 27.2 | K25: 29.057143 | L25: 0 | M25: =K25*(1+L$70*L25) -> 29.057143 | N25: =M25/B25 -> 0.00023986613 | O25: =O24+N25 -> 0.92779339 | P25: =P24+M25 -> 91076.743 | Q25: =O24 -> 0.92755352
A26: 24 | B26: 120733 | D26: =Varicella!B$23/10 -> 38.4 | E26: =Varicella!C$23/10 -> 28.6 | F26: =Varicella!D$23/10 -> 29.6 | G26: =Varicella!E$23/10 -> 26.1 | H26: =Varicella!F$23/10 -> 26.6 | I26: =Varicella!G$23/10 -> 26.9 | J26: =Varicella!H$23/10 -> 27.2 | K26: 29.057143 | L26: 0 | M26: =K26*(1+L$70*L26) -> 29.057143 | N26: =M26/B26 -> 0.00024067275 | O26: =O25+N26 -> 0.92803406 | P26: =P25+M26 -> 91105.8 | Q26: =O25 -> 0.92779339
A27: 25 | B27: 123054 | D27: =Varicella!B$23/10 -> 38.4 | E27: =Varicella!C$23/10 -> 28.6 | F27: =Varicella!D$23/10 -> 29.6 | G27: =Varicella!E$23/10 -> 26.1 | H27: =Varicella!F$23/10 -> 26.6 | I27: =Varicella!G$23/10 -> 26.9 | J27: =Varicella!H$23/10 -> 27.2 | K27: 29.057143 | L27: 0 | M27: =K27*(1+L$70*L27) -> 29.057143 | N27: =M27/B27 -> 0.00023613327 | O27: =O26+N27 -> 0.92827019 | P27: =P26+M27 -> 91134.857 | Q27: =O26 -> 0.92803406
A28: 26 | B28: 121455 | D28: =Varicella!B$23/10 -> 38.4 | E28: =Varicella!C$23/10 -> 28.6 | F28: =Varicella!D$23/10 -> 29.6 | G28: =Varicella!E$23/10 -> 26.1 | H28: =Varicella!F$23/10 -> 26.6 | I28: =Varicella!G$23/10 -> 26.9 | J28: =Varicella!H$23/10 -> 27.2 | K28: 29.057143 | L28: 0 | M28: =K28*(1+L$70*L28) -> 29.057143 | N28: =M28/B28 -> 0.00023924205 | O28: =O27+N28 -> 0.92850944 | P28: =P27+M28 -> 91163.915 | Q28: =O27 -> 0.92827019
A29: 27 | B29: 117711 | D29: =Varicella!B$23/10 -> 38.4 | E29: =Varicella!C$23/10 -> 28.6 | F29: =Varicella!D$23/10 -> 29.6 | G29: =Varicella!E$23/10 -> 26.1 | H29: =Varicella!F$23/10 -> 26.6 | I29: =Varicella!G$23/10 -> 26.9 | J29: =Varicella!H$23/10 -> 27.2 | K29: 29.057143 | L29: 0 | M29: =K29*(1+L$70*L29) -> 29.057143 | N29: =M29/B29 -> 0.00024685155 | O29: =O28+N29 -> 0.92875629 | P29: =P28+M29 -> 91192.972 | Q29: =O28 -> 0.92850944
A30: 28 | B30: 121151 | D30: =Varicella!B$23/10 -> 38.4 | E30: =Varicella!C$23/10 -> 28.6 | F30: =Varicella!D$23/10 -> 29.6 | G30: =Varicella!E$23/10 -> 26.1 | H30: =Varicella!F$23/10 -> 26.6 | I30: =Varicella!G$23/10 -> 26.9 | J30: =Varicella!H$23/10 -> 27.2 | K30: 29.057143 | L30: 0 | M30: =K30*(1+L$70*L30) -> 29.057143 | N30: =M30/B30 -> 0.00023984237 | O30: =O29+N30 -> 0.92899613 | P30: =P29+M30 -> 91222.029 | Q30: =O29 -> 0.92875629
A31: 29 | B31: 127930 | D31: =Varicella!B$23/10 -> 38.4 | E31: =Varicella!C$23/10 -> 28.6 | F31: =Varicella!D$23/10 -> 29.6 | G31: =Varicella!E$23/10 -> 26.1 | H31: =Varicella!F$23/10 -> 26.6 | I31: =Varicella!G$23/10 -> 26.9 | J31: =Varicella!H$23/10 -> 27.2 | K31: 29.057143 | L31: 0 | M31: =K31*(1+L$70*L31) -> 29.057143 | N31: =M31/B31 -> 0.00022713314 | O31: =O30+N31 -> 0.92922326 | P31: =P30+M31 -> 91251.086 | Q31: =O30 -> 0.92899613
A32: 30 | B32: 137472 | D32: =Varicella!B$24/10 -> 47.5 | E32: =Varicella!C$24/10 -> 36.7 | F32: =Varicella!D$24/10 -> 28.3 | G32: =Varicella!E$24/10 -> 23.5 | H32: =Varicella!F$24/10 -> 24.9 | I32: =Varicella!G$24/10 -> 22.8 | J32: =Varicella!H$24/10 -> 22.2 | K32: 29.414286 | L32: 0 | M32: =K32*(1+L$70*L32) -> 29.414286 | N32: =M32/B32 -> 0.00021396565 | O32: =O31+N32 -> 0.92943723 | P32: =P31+M32 -> 91280.5 | Q32: =O31 -> 0.92922326
A33: 31 | B33: 145146 | D33: =Varicella!B$24/10 -> 47.5 | E33: =Varicella!C$24/10 -> 36.7 | F33: =Varicella!D$24/10 -> 28.3 | G33: =Varicella!E$24/10 -> 23.5 | H33: =Varicella!F$24/10 -> 24.9 | I33: =Varicella!G$24/10 -> 22.8 | J33: =Varicella!H$24/10 -> 22.2 | K33: 29.414286 | L33: 0 | M33: =K33*(1+L$70*L33) -> 29.414286 | N33: =M33/B33 -> 0.00020265309 | O33: =O32+N33 -> 0.92963988 | P33: =P32+M33 -> 91309.915 | Q33: =O32 -> 0.92943723
A34: 32 | B34: 151791 | D34: =Varicella!B$24/10 -> 47.5 | E34: =Varicella!C$24/10 -> 36.7 | F34: =Varicella!D$24/10 -> 28.3 | G34: =Varicella!E$24/10 -> 23.5 | H34: =Varicella!F$24/10 -> 24.9 | I34: =Varicella!G$24/10 -> 22.8 | J34: =Varicella!H$24/10 -> 22.2 | K34: 29.414286 | L34: 0 | M34: =K34*(1+L$70*L34) -> 29.414286 | N34: =M34/B34 -> 0.00019378149 | O34: =O33+N34 -> 0.92983366 | P34: =P33+M34 -> 91339.329 | Q34: =O33 -> 0.92963988
A35: 33 | B35: 161739 | D35: =Varicella!B$24/10 -> 47.5 | E35: =Varicella!C$24/10 -> 36.7 | F35: =Varicella!D$24/10 -> 28.3 | G35: =Varicella!E$24/10 -> 23.5 | H35: =Varicella!F$24/10 -> 24.9 | I35: =Varicella!G$24/10 -> 22.8 | J35: =Varicella!H$24/10 -> 22.2 | K35: 29.414286 | L35: 0 | M35: =K35*(1+L$70*L35) -> 29.414286 | N35: =M35/B35 -> 0.00018186267 | O35: =O34+N35 -> 0.93001553 | P35: =P34+M35 -> 91368.743 | Q35: =O34 -> 0.92983366
A36: 34 | B36: 169169 | D36: =Varicella!B$24/10 -> 47.5 | E36: =Varicella!C$24/10 -> 36.7 | F36: =Varicella!D$24/10 -> 28.3 | G36: =Varicella!E$24/10 -> 23.5 | H36: =Varicella!F$24/10 -> 24.9 | I36: =Varicella!G$24/10 -> 22.8 | J36: =Varicella!H$24/10 -> 22.2 | K36: 29.414286 | L36: 0 | M36: =K36*(1+L$70*L36) -> 29.414286 | N36: =M36/B36 -> 0.00017387515 | O36: =O35+N36 -> 0.9301894 | P36: =P35+M36 -> 91398.157 | Q36: =O35 -> 0.93001553
A37: 35 | B37: 176095 | D37: =Varicella!B$24/10 -> 47.5 | E37: =Varicella!C$24/10 -> 36.7 | F37: =Varicella!D$24/10 -> 28.3 | G37: =Varicella!E$24/10 -> 23.5 | H37: =Varicella!F$24/10 -> 24.9 | I37: =Varicella!G$24/10 -> 22.8 | J37: =Varicella!H$24/10 -> 22.2 | K37: 29.414286 | L37: 0 | M37: =K37*(1+L$70*L37) -> 29.414286 | N37: =M37/B37 -> 0.00016703646 | O37: =O36+N37 -> 0.93035644 | P37: =P36+M37 -> 91427.572 | Q37: =O36 -> 0.9301894
A38: 36 | B38: 184454 | D38: =Varicella!B$24/10 -> 47.5 | E38: =Varicella!C$24/10 -> 36.7 | F38: =Varicella!D$24/10 -> 28.3 | G38: =Varicella!E$24/10 -> 23.5 | H38: =Varicella!F$24/10 -> 24.9 | I38: =Varicella!G$24/10 -> 22.8 | J38: =Varicella!H$24/10 -> 22.2 | K38: 29.414286 | L38: 0 | M38: =K38*(1+L$70*L38) -> 29.414286 | N38: =M38/B38 -> 0.00015946678 | O38: =O37+N38 -> 0.9305159 | P38: =P37+M38 -> 91456.986 | Q38: =O37 -> 0.93035644
A39: 37 | B39: 165215 | D39: =Varicella!B$24/10 -> 47.5 | E39: =Varicella!C$24/10 -> 36.7 | F39: =Varicella!D$24/10 -> 28.3 | G39: =Varicella!E$24/10 -> 23.5 | H39: =Varicella!F$24/10 -> 24.9 | I39: =Varicella!G$24/10 -> 22.8 | J39: =Varicella!H$24/10 -> 22.2 | K39: 29.414286 | L39: 0 | M39: =K39*(1+L$70*L39) -> 29.414286 | N39: =M39/B39 -> 0.00017803641 | O39: =O38+N39 -> 0.93069394 | P39: =P38+M39 -> 91486.4 | Q39: =O38 -> 0.9305159
A40: 38 | B40: 147121 | D40: =Varicella!B$24/10 -> 47.5 | E40: =Varicella!C$24/10 -> 36.7 | F40: =Varicella!D$24/10 -> 28.3 | G40: =Varicella!E$24/10 -> 23.5 | H40: =Varicella!F$24/10 -> 24.9 | I40: =Varicella!G$24/10 -> 22.8 | J40: =Varicella!H$24/10 -> 22.2 | K40: 29.414286 | L40: 0 | M40: =K40*(1+L$70*L40) -> 29.414286 | N40: =M40/B40 -> 0.00019993261 | O40: =O39+N40 -> 0.93089387 | P40: =P39+M40 -> 91515.815 | Q40: =O39 -> 0.93069394
A41: 39 | B41: 142711 | D41: =Varicella!B$24/10 -> 47.5 | E41: =Varicella!C$24/10 -> 36.7 | F41: =Varicella!D$24/10 -> 28.3 | G41: =Varicella!E$24/10 -> 23.5 | H41: =Varicella!F$24/10 -> 24.9 | I41: =Varicella!G$24/10 -> 22.8 | J41: =Varicella!H$24/10 -> 22.2 | K41: 29.414286 | L41: 0 | M41: =K41*(1+L$70*L41) -> 29.414286 | N41: =M41/B41 -> 0.00020611085 | O41: =O40+N41 -> 0.93109998 | P41: =P40+M41 -> 91545.229 | Q41: =O40 -> 0.93089387
...

Sheet Varicella
A1: Varicella | B1: 2011 | C1: 2012 | D1: 2013 | E1: 2014 | F1: 2015 | G1: 2016 | H1: 2017 | I1: Átlag | J1: Korrigált átlag
A2: 0 | B2: 1245 | C2: 1070 | D2: 1252 | E2: 1052 | F2: 1577 | G2: 1518 | H2: 1343 | I2: =AVERAGE(B2:H2) -> 1293.8571 | J2: =I2*J$30 -> 3622.8
A3: 1 | B3: 2342 | C3: 1700 | D3: 1988 | E3: 1662 | F3: 2581 | G3: 2473 | H3: 1984 | I3: =AVERAGE(B3:H3) -> 2104.2857 | J3: =I3*J$30 -> 5892
A4: 2 | B4: 3436 | C4: 2639 | D4: 2665 | E4: 2308 | F4: 3747 | G4: 3210 | H4: 2685 | I4: =AVERAGE(B4:H4) -> 2955.7143 | J4: =I4*J$30 -> 8276
A5: 3 | B5: 6657 | C5: 5740 | D5: 5792 | E5: 4713 | F5: 6992 | G5: 6336 | H5: 5282 | I5: =AVERAGE(B5:H5) -> 5930.2857 | J5: =I5*J$30 -> 16604.8
A6: 4 | B6: 7244 | C6: 6281 | D6: 6387 | E6: 5225 | F6: 7376 | G6: 6539 | H6: 5779 | I6: =AVERAGE(B6:H6) -> 6404.4286 | J6: =I6*J$30 -> 17932.4
A7: 5 | B7: 6077 | C7: 5140 | D7: 5234 | E7: 4560 | F7: 6539 | G7: 5405 | H7: 4743 | I7: =AVERAGE(B7:H7) -> 5385.4286 | J7: =I7*J$30 -> 15079.2
A8: 6 | B8: 4132 | C8: 3516 | D8: 3790 | E8: 3200 | F8: 4523 | G8: 4056 | H8: 3460 | I8: =AVERAGE(B8:H8) -> 3811 | J8: =I8*J$30 -> 10670.8
A9: 7 | B9: 2362 | C9: 1972 | D9: 2125 | E9: 1808 | F9: 2551 | G9: 2332 | H9: 2147 | I9: =AVERAGE(B9:H9) -> 2185.2857 | J9: =I9*J$30 -> 6118.8
A10: 8 | B10: 1581 | C10: 1363 | D10: 1268 | E10: 1068 | F10: 1609 | G10: 1564 | H10: 1657 | I10: =AVERAGE(B10:H10) -> 1444.2857 | J10: =I10*J$30 -> 4044
A11: 9 | B11: 1198 | C11: 804 | D11: 890 | E11: 647 | F11: 1038 | G11: 1068 | H11: 1043 | I11: =AVERAGE(B11:H11) -> 955.42857 | J11: =I11*J$30 -> 2675.2
A12: 10 | B12: 754 | C12: 608 | D12: 638 | E12: 520 | F12: 692 | G12: 761 | H12: 755 | I12: =AVERAGE(B12:H12) -> 675.42857 | J12: =I12*J$30 -> 1891.2
A13: 11 | B13: 553 | C13: 496 | D13: 510 | E13: 350 | F13: 460 | G13: 535 | H13: 482 | I13: =AVERAGE(B13:H13) -> 483.71429 | J13: =I13*J$30 -> 1354.4
... A17: 0 | B17: 1245 | C17: 1070 | D17: 1252 | E17: 1052 | F17: 1577 | G17: 1518 | H17: 1343 | I17: =AVERAGE(B17:H17) -> 1293.8571 | J17: =I17*J$30 -> 3622.8
A18: 1-2 | B18: 5778 | C18: 4339 | D18: 4653 | E18: 3970 | F18: 6328 | G18: 5683 | H18: 4669 | I18: =AVERAGE(B18:H18) -> 5060 | J18: =I18*J$30 -> 14168
A19: 3-5 | B19: 19978 | C19: 17161 | D19: 17413 | E19: 14498 | F19: 20907 | G19: 18280 | H19: 15804 | I19: =AVERAGE(B19:H19) -> 17720.143 | J19: =I19*J$30 -> 49616.4
A20: 6-9 | B20: 9273 | C20: 7655 | D20: 8073 | E20: 6723 | F20: 9721 | G20: 9020 | H20: 8307 | I20: =AVERAGE(B20:H20) -> 8396 | J20: =I20*J$30 -> 23508.8
A21: 10-14 | B21: 2458 | C21: 1971 | D21: 2011 | E21: 1590 | F21: 1982 | G21: 2227 | H21: 2175 | I21: =AVERAGE(B21:H21) -> 2059.1429 | J21: =I21*J$30 -> 5765.6
A22: 15-19 | B22: 648 | C22: 458 | D22: 483 | E22: 435 | F22: 469 | G22: 472 | H22: 475 | I22: =AVERAGE(B22:H22) -> 491.42857 | J22: =I22*J$30 -> 1376
A23: 20-29 | B23: 384 | C23: 286 | D23: 296 | E23: 261 | F23: 266 | G23: 269 | H23: 272 | I23: =AVERAGE(B23:H23) -> 290.57143 | J23: =I23*J$30 -> 813.6
A24: 30-39 | B24: 475 | C24: 367 | D24: 283 | E24: 235 | F24: 249 | G24: 228 | H24: 222 | I24: =AVERAGE(B24:H24) -> 294.14286 | J24: =I24*J$30 -> 823.6
A25: 40-49 | B25: 105 | C25: 109 | D25: 97 | E25: 79 | F25: 90 | G25: 109 | H25: 87 | I25: =AVERAGE(B25:H25) -> 96.571429 | J25: =I25*J$30 -> 270.4
A26: 50-59 | B26: 23 | C26: 26 | D26: 23 | E26: 31 | F26: 21 | G26: 26 | H26: 18 | I26: =AVERAGE(B26:H26) -> 24 | J26: =I26*J$30 -> 67.2
A27: 60- | B27: 22 | C27: 12 | D27: 14 | E27: 8 | F27: 10 | G27: 11 | H27: 20 | I27: =AVERAGE(B27:H27) -> 13.857143 | J27: =I27*J$30 -> 38.8
A28: Összesen | B28: 40389 | C28: 33454 | D28: 34598 | E28: 28882 | F28: 41620 | G28: 37843 | H28: 33392 | I28: =AVERAGE(B28:H28) -> 35739.714 | J28: =I28*J$30 -> 100071.2
J29: Korrigáló tényező
J30: 2.8
